import React from 'react'
import { render, screen } from '@testing-library/react'
import '@testing-library/jest-dom'
import ErrorBoundary from '../../components/ErrorBoundary'

// Mock console.error to avoid noise in test output
const originalError = console.error
beforeAll(() => {
  console.error = jest.fn()
})

afterAll(() => {
  console.error = originalError
})

// Component that throws an error for testing
const ThrowError = ({ shouldThrow }: { shouldThrow: boolean }) => {
  if (shouldThrow) {
    throw new Error('Test error')
  }
  return <div>No error</div>
}

describe('ErrorBoundary', () => {
  beforeEach(() => {
    jest.clearAllMocks()
  })

  it('should render children when there is no error', () => {
    render(
      <ErrorBoundary>
        <div>Test content</div>
      </ErrorBoundary>
    )

    expect(screen.getByText('Test content')).toBeInTheDocument()
  })

  it('should render error UI when there is an error', () => {
    render(
      <ErrorBoundary>
        <ThrowError shouldThrow={true} />
      </ErrorBoundary>
    )

    expect(screen.getByText('Something went wrong')).toBeInTheDocument()
    expect(screen.getByText('Try again')).toBeInTheDocument()
  })

  it('should recover when try again is clicked', () => {
    const { rerender } = render(
      <ErrorBoundary>
        <ThrowError shouldThrow={true} />
      </ErrorBoundary>
    )

    // Error should be displayed
    expect(screen.getByText('Something went wrong')).toBeInTheDocument()

    // Click try again button
    const tryAgainButton = screen.getByText('Try again')
    tryAgainButton.click()

    // Re-render with no error
    rerender(
      <ErrorBoundary>
        <ThrowError shouldThrow={false} />
      </ErrorBoundary>
    )

    expect(screen.getByText('No error')).toBeInTheDocument()
  })

  it('should call onError callback when error occurs', () => {
    const onError = jest.fn()

    render(
      <ErrorBoundary onError={onError}>
        <ThrowError shouldThrow={true} />
      </ErrorBoundary>
    )

    expect(onError).toHaveBeenCalledWith(
      expect.any(Error),
      expect.objectContaining({
        componentStack: expect.any(String)
      })
    )
  })

  it('should show custom fallback when provided', () => {
    const customFallback = <div>Custom error message</div>

    render(
      <ErrorBoundary fallback={customFallback}>
        <ThrowError shouldThrow={true} />
      </ErrorBoundary>
    )

    expect(screen.getByText('Custom error message')).toBeInTheDocument()
  })

  it('should log error details to console', () => {
    const mockConsoleError = console.error as jest.Mock

    render(
      <ErrorBoundary>
        <ThrowError shouldThrow={true} />
      </ErrorBoundary>
    )

    expect(mockConsoleError).toHaveBeenCalledWith(
      'ErrorBoundary caught an error:',
      expect.any(Error),
      expect.any(Object)
    )
  })
})